Workbook

Sheet included_studies
A1: Disorder | B1: Title | C1: Authors | D1: Year | E1: Study_ID | F1: Study_Design | G1: Blinding | H1: Intervention_group | I1: Control_group | J1: Sample_Size_PD_int | K1: Sample_Size_PD_con | L1: Sample_Size_HC | M1: N_Male_PD_int | N1: N_Female_PD_int | O1: N_Male_PD_con | P1: N_Female_PD_con | Q1: N_Male_HC | R1: N_Female_HC | S1: Handedness_PD_int | T1: Handedness_PD_con | U1: Handedness_HC | V1: Age_mean_PD_int | W1: Age_SD_PD_int | X1: Age_mean_PD_con | Y1: Age_SD_PD_con | Z1: Age_mean_HC | AA1: Age_SD_HC | AB1: Disease_duration_months_mean_int | AC1: Disease_duration_months_sd_int | AD1: Disease_duration_months_mean_con | AE1: Disease_duration_months_sd_con | AF1: Drugs_intake_mg_mean_int | AG1: Drugs_intake_mg_sd_int | AH1: Drugs_intake_mg_mean_con | AI1: Drugs_intake_mg_sd_con | AJ1: Global_Cognition_MoCA_int | AK1: Global_Cognition_MoCA_con | AL1: Physiotherapy_int | AM1: Physiotherapy_con | AN1: Psychotherapy_int | AO1: Psychotherapy_con | AP1: Electrode_size_cm2_stim | AQ1: Electrode_size_cm2_return | AR1: Electrode_shape_stim | AS1: Electrode_shape_return | AT1: Electrode_material | AU1: Loc_Stimulation_Electrode_int | AV1: Loc_Stimulation_Electrode_con | AW1: Loc_Return_Electrode_int | AX1: Loc_Return_Electrode_con | AY1: Frequency_Hz_int | AZ1: Frequency_Hz_con | BA1: Ramping_up_sec | BB1: Ramping_down_sec | BC1: Intensity_pp_mA | BD1: Duration_min | BE1: N_Sessions | BF1: Timepoints_of_measurement | BG1: Outcome | BH1: Outcome_category | BI1: Direction_improvement | BJ1: on_off_med | BK1: Online_Offline_stim | BL1: Mean_pre_HC | BM1: SD_pre_HC | BN1: Mean_pre_int | BO1: SD_pre_int | BP1: Mean_pre_con | BQ1: SD_pre_con | BR1: Mean_during_int | BS1: SD_during_int | BT1: Mean_during_con | BU1: SD_during_con | BV1: Mean_post_immediate_int | BW1: SD_post_immediate_int | BX1: Mean_post_immediate_con | BY1: SD_post_immediate_con | BZ1: Mean_post_intermediate_int | CA1: SD_post_intermediate_int | CB1: Mean_post_intermediate_con | CC1: SD_post_intermediate_con | CD1: Mean_post_long_int | CE1: SD_post_long_int | CF1: Mean_post_long_con | CG1: SD_post_long_con | CH1: p_value | CI1: Effect_Size | CJ1: Main_finding
A2: AD | B2: Impact of 40 Hz Transcranial Alternating Current Stimulation on Cerebral Tau Burden in Patients with Alzheimer’s Disease: A Case Series | C2: Dhaynaut, M., Sprugnoli, G., Cappon, D., Macone, J., Sanchez, J. S., Normandin, M. D., Guehl, N. J., Koch, G., Paciorek, R., Connor, A., Press, D., Johnson, K., Pascual-Leone, A., El Fakhri, G., & Santarnecchi, E. | D2: 2022 | E2: 57
A3: AD | B3: Modulation of Cortical and Hippocampal Functional MRI Connectivity Following Transcranial Alternating Current Stimulation in Mild Alzheimer Disease | C3: Wang, T. | D3: 2025 | E3: 58 | F3: 1 | G3: 1 | H3: 40 Hz Gamma tACS | I3: Sham tACS | J3: 23 | K3: 23 | M3: 7 | N3: 16 | O3: 9 | P3: 14 | S3: 1 | T3: 1 | V3: 66 | X3: 64 | AL3: 0 | AM3: 0 | AN3: 0 | AO3: 0 | AY3: 40 | AZ3: sham | BC3: 15 | BD3: 60 | BE3: 30 | BG3: Mini Mental State Examination (MMSE) | BH3: 1 | BI3: 1 | BJ3: 1 | BK3: 0 | BN3: 19 | BP3: 20
A4: AD | B4: Modulation of Cortical and Hippocampal Functional MRI Connectivity Following Transcranial Alternating Current Stimulation in Mild Alzheimer Disease | C4: Wang, T. | D4: 2025 | E4: 58 | BG4: Montreal Cognitive Assessment (MoCA) | BH4: 1 | BI4: 1
A5: AD | B5: Modulation of Cortical and Hippocampal Functional MRI Connectivity Following Transcranial Alternating Current Stimulation in Mild Alzheimer Disease | C5: Wang, T. | D5: 2025 | E5: 58 | BG5: AD Assessment Scale - Cognitive subscale (ADAS-cog) | BH5: 1 | BI5: 0
A6: AD | B6: Modulation of Cortical and Hippocampal Functional MRI Connectivity Following Transcranial Alternating Current Stimulation in Mild Alzheimer Disease | C6: Wang, T. | D6: 2025 | E6: 58 | BG6: WHO-UCLA Auditory Verbal Test - Immediate Recall (AVLT-IR) | BH6: 1
A7: AD | B7: Modulation of Cortical and Hippocampal Functional MRI Connectivity Following Transcranial Alternating Current Stimulation in Mild Alzheimer Disease | C7: Wang, T. | D7: 2025 | E7: 58 | BG7: WHO-UCLA Auditory Verbal Test - Delayed Recall (AVLT-DR) | BH7: 1
A8: AD | B8: Modulation of Cortical and Hippocampal Functional MRI Connectivity Following Transcranial Alternating Current Stimulation in Mild Alzheimer Disease | C8: Wang, T. | D8: 2025 | E8: 58 | BG8: WHO-UCLA Auditory Verbal Test - Recognition Recall (AVLT-R-R) | BH8: 1
A9: AD | B9: Modulation of Cortical and Hippocampal Functional MRI Connectivity Following Transcranial Alternating Current Stimulation in Mild Alzheimer Disease | C9: Wang, T. | D9: 2025 | E9: 58 | BG9: Trail Making Test Part A (TMT-A) | BH9: 1
A10: AD | B10: Modulation of Cortical and Hippocampal Functional MRI Connectivity Following Transcranial Alternating Current Stimulation in Mild Alzheimer Disease | C10: Wang, T. | D10: 2025 | E10: 58 | BG10: Trail Making Test Part B (TMT-B) | BH10: 1
A11: AD | B11: Modulation of Cortical and Hippocampal Functional MRI Connectivity Following Transcranial Alternating Current Stimulation in Mild Alzheimer Disease | C11: Wang, T. | D11: 2025 | E11: 58 | BG11: Boston Naming Test (BNT) | BH11: 1
A12: AD | B12: Modulation of Cortical and Hippocampal Functional MRI Connectivity Following Transcranial Alternating Current Stimulation in Mild Alzheimer Disease | C12: Wang, T. | D12: 2025 | E12: 58 | BG12: FC LHIP-LMCG (Left hippocampus, Left middle cingulate gyrus) | BH12: 3
A13: AD | B13: Modulation of Cortical and Hippocampal Functional MRI Connectivity Following Transcranial Alternating Current Stimulation in Mild Alzheimer Disease | C13: Wang, T. | D13: 2025 | E13: 58 | BG13: FC LHIP-LMFG (Left hippocampus, Left middle frontal gyrus) | BH13: 3
A14: AD | B14: Modulation of Cortical and Hippocampal Functional MRI Connectivity Following Transcranial Alternating Current Stimulation in Mild Alzheimer Disease | C14: Wang, T. | D14: 2025 | E14: 58 | BG14: FC RHIP-RFusG (Right hippocampus, Right fusiform gyrus) | BH14: 3
A15: AD | B15: Modulation of Cortical and Hippocampal Functional MRI Connectivity Following Transcranial Alternating Current Stimulation in Mild Alzheimer Disease | C15: Wang, T. | D15: 2025 | E15: 58 | BG15: FC LEC-RMTG (Left entorhinal cortex, Right middle temporal gyrus) | BH15: 3
A16: AD | B16: Modulation of Cortical and Hippocampal Functional MRI Connectivity Following Transcranial Alternating Current Stimulation in Mild Alzheimer Disease | C16: Wang, T. | D16: 2025 | E16: 58 | BG16: FC REC-RFusG (Right entorhinal cortex, Right fusiform gyrus) | BH16: 3
A17: AD | B17: TRanscranial AlterNating current stimulation FOR patients with mild Alzheimer’s Disease (TRANSFORM-AD): a randomized controlled clinical trial | C17: Tang, Y. | D17: 2024 | E17: 59 | F17: 1 | G17: 1 | H17: 40 Hz Gamma tACS | J17: 23 | K17: 23 | M17: 7 | N17: 16 | O17: 9 | P17: 14 | S17: 1 | T17: 1 | V17: 68.57 | W17: 5.21 | X17: 63.7 | Y17: 6.05 | AJ17: 14.52 | AK17: 15.74 | AL17: 0 | AM17: 0 | AN17: 0 | AO17: 0 | AP17: 4.45 x 9.53 | AQ17: 3.18 x 3.81 | AR17: 0 | AS17: 0 | AT17: 2 | AU17: Fpz, Fp1, Fp2 | AV17: Fpz, Fp1, Fp2 | AW17: Mastoid region | AX17: Mastoid region | AY17: 40 | AZ17: sham | BC17: 15 | BD17: 60 | BE17: 30 | BG17: AD Assessment Scale - Cognitive subscale (ADAS-cog) | BH17: 1 | BI17: 0 | BJ17: 1 | BK17: 0 | BN17: 18.22 | BO17: 5.92 | BP17: 17.3 | BQ17: 5.98
A18: AD | B18: TRanscranial AlterNating current stimulation FOR patients with mild Alzheimer’s Disease (TRANSFORM-AD): a randomized controlled clinical trial | C18: Tang, Y. | D18: 2024 | E18: 59 | BG18: Mini Mental State Examination (MMSE) | BH18: 1 | BI18: 1 | BN18: 19.43 | BO18: 3.33 | BP18: 20.78 | BQ18: 3.04
A19: AD | B19: TRanscranial AlterNating current stimulation FOR patients with mild Alzheimer’s Disease (TRANSFORM-AD): a randomized controlled clinical trial | C19: Tang, Y. | D19: 2024 | E19: 59 | BG19: Montreal Cognitive Assessment (MoCA) | BH19: 1 | BI19: 1 | BN19: 14.52 | BO19: 3.82 | BP19: 15.74 | BQ19: 3.99
A20: AD | B20: TRanscranial AlterNating current stimulation FOR patients with mild Alzheimer’s Disease (TRANSFORM-AD): a randomized controlled clinical trial | C20: Tang, Y. | D20: 2024 | E20: 59 | BG20: WHO-UCLA Auditory Verbal Test - Immediate Recall (AVLT-IR) | BH20: 1 | BN20: 14.78 | BO20: 5.95 | BP20: 14.83 | BQ20: 4.54
A21: AD | B21: TRanscranial AlterNating current stimulation FOR patients with mild Alzheimer’s Disease (TRANSFORM-AD): a randomized controlled clinical trial | C21: Tang, Y. | D21: 2024 | E21: 59 | BG21: WHO-UCLA Auditory Verbal Test - Delayed Recall (AVLT-DR) | BH21: 1 | BN21: 1.04 | BO21: 1.29 | BP21: 1 | BQ21: 1.2
A22: AD | B22: TRanscranial AlterNating current stimulation FOR patients with mild Alzheimer’s Disease (TRANSFORM-AD): a randomized controlled clinical trial | C22: Tang, Y. | D22: 2024 | E22: 59 | BG22: WHO-UCLA Auditory Verbal Test - Recognition Recall (AVLT-R-R) | BH22: 1 | BN22: 6.09 | BO22: 3.48 | BP22: 5.65 | BQ22: 2.98
A23: AD | B23: TRanscranial AlterNating current stimulation FOR patients with mild Alzheimer’s Disease (TRANSFORM-AD): a randomized controlled clinical trial | C23: Tang, Y. | D23: 2024 | E23: 59 | BG23: Digit Span Forward | BH23: 1 | BN23: 7 | BO23: 1.41 | BP23: 7.39 | BQ23: 1.08
A24: AD | B24: TRanscranial AlterNating current stimulation FOR patients with mild Alzheimer’s Disease (TRANSFORM-AD): a randomized controlled clinical trial | C24: Tang, Y. | D24: 2024 | E24: 59 | BG24: Digit Span Backward | BH24: 1 | BN24: 3.66 | BO24: 0.98 | BP24: 4.04 | BQ24: 1.29
A25: AD | B25: TRanscranial AlterNating current stimulation FOR patients with mild Alzheimer’s Disease (TRANSFORM-AD): a randomized controlled clinical trial | C25: Tang, Y. | D25: 2024 | E25: 59 | BG25: Boston Naming Test (BNT) | BH25: 1 | BN25: 20.83 | BO25: 3.52 | BP25: 20.74 | BQ25: 4.87
A26: AD | B26: TRanscranial AlterNating current stimulation FOR patients with mild Alzheimer’s Disease (TRANSFORM-AD): a randomized controlled clinical trial | C26: Tang, Y. | D26: 2024 | E26: 59 | BG26: Trail Making Test (TMT B-A) | BH26: 1 | BN26: 111.7 | BO26: 82.42 | BP26: 107.13 | BQ26: 84.06
A27: AD | B27: TRanscranial AlterNating current stimulation FOR patients with mild Alzheimer’s Disease (TRANSFORM-AD): a randomized controlled clinical trial | C27: Tang, Y. | D27: 2024 | E27: 59 | BG27: Activities of Daily Living (ADL) | BH27: 1 | BN27: 24.55 | BO27: 3.23 | BP27: 26.09 | BQ27: 4.43
A28: AD | B28: TRanscranial AlterNating current stimulation FOR patients with mild Alzheimer’s Disease (TRANSFORM-AD): a randomized controlled clinical trial | C28: Tang, Y. | D28: 2024 | E28: 59 | BG28: Neuropsychiatric Inventory (NPI) | BH28: 2
A29: AD | B29: TRanscranial AlterNating current stimulation FOR patients with mild Alzheimer’s Disease (TRANSFORM-AD): a randomized controlled clinical trial | C29: Tang, Y. | D29: 2024 | E29: 59 | BG29: Geriatric Depression Scale (GDS) | BH29: 2
A30: AD | B30: TRanscranial AlterNating current stimulation FOR patients with mild Alzheimer’s Disease (TRANSFORM-AD): a randomized controlled clinical trial | C30: Tang, Y. | D30: 2024 | E30: 59 | BG30: Gamma Power Change (Left Frontal) | BH30: 3
A31: AD | B31: TRanscranial AlterNating current stimulation FOR patients with mild Alzheimer’s Disease (TRANSFORM-AD): a randomized controlled clinical trial | C31: Tang, Y. | D31: 2024 | E31: 59 | BG31: Gamma Power Change (Right Frontal) | BH31: 3
A32: AD | B32: TRanscranial AlterNating current stimulation FOR patients with mild Alzheimer’s Disease (TRANSFORM-AD): a randomized controlled clinical trial | C32: Tang, Y. | D32: 2024 | E32: 59 | BG32: Gamma Power Change (Left Parietal) | BH32: 3
A33: AD | B33: TRanscranial AlterNating current stimulation FOR patients with mild Alzheimer’s Disease (TRANSFORM-AD): a randomized controlled clinical trial | C33: Tang, Y. | D33: 2024 | E33: 59 | BG33: Gamma Power Change (Right Parietal) | BH33: 3
A34: AD | B34: TRanscranial AlterNating current stimulation FOR patients with mild Alzheimer’s Disease (TRANSFORM-AD): a randomized controlled clinical trial | C34: Tang, Y. | D34: 2024 | E34: 59 | BG34: Change in theta-gamma coupling (left hippocampus) | BH34: 3
A35: AD | B35: TRanscranial AlterNating current stimulation FOR patients with mild Alzheimer’s Disease (TRANSFORM-AD): a randomized controlled clinical trial | C35: Tang, Y. | D35: 2024 | E35: 59 | BG35: Change in theta-gamma coupling (Right hippocampus) | BH35: 3
A36: AD | B36: TRanscranial AlterNating current stimulation FOR patients with mild Alzheimer’s Disease (TRANSFORM-AD): a randomized controlled clinical trial | C36: Tang, Y. | D36: 2024 | E36: 59 | BG36: Average fractional amplitude of low-frequency fluctuation (fALFF) (left hippocampus) | BH36: 3
A37: AD | B37: TRanscranial AlterNating current stimulation FOR patients with mild Alzheimer’s Disease (TRANSFORM-AD): a randomized controlled clinical trial | C37: Tang, Y. | D37: 2024 | E37: 59 | BG37: Average fractional amplitude of low-frequency fluctuation (fALFF) (right hippocampus) | BH37: 3
A38: AD | B38: Altered Neuronal Activity Patterns of thePrefrontal Cortex in Alzheimer’s DiseaseAfter Transcranial Alternating CurrentStimulation: A Resting-State fMRI Study | C38: Wang, T. | D38: 2024 | E38: 60 | F38: 1 | H38: 40 Hz Gamma tACS | I38: Sham tACS | J38: 23 | K38: 23 | M38: 16 | N38: 30 | O38: 7 | P38: 16 | S38: 1 | T38: 1 | V38: 64.78 | W38: 5.69 | X38: 65.87 | Y38: 63.7 | AL38: 0 | AM38: 0 | AN38: 0 | AO38: 0 | BC38: 15 | BD38: 60 | BE38: 30 | BG38: AD Assessment Scale - Cognitive subscale (ADAS-cog) | BH38: 1
A39: AD | B39: Altered Neuronal Activity Patterns of thePrefrontal Cortex in Alzheimer’s DiseaseAfter Transcranial Alternating CurrentStimulation: A Resting-State fMRI Study | C39: Wang, T. | D39: 2024 | E39: 60 | BG39: Mini Mental State Examination (MMSE) | BH39: 1
A40: AD | B40: Altered Neuronal Activity Patterns of thePrefrontal Cortex in Alzheimer’s DiseaseAfter Transcranial Alternating CurrentStimulation: A Resting-State fMRI Study | C40: Wang, T. | D40: 2024 | E40: 60 | BG40: Montreal Cognitive Assessment (MoCA) | BH40: 1
...

Sheet disorder_overview
A1: Psychiatric Disorders | C1: Neurodegenerative Disorders | E1: Other Disorders
A2: Schizophrenia | B2: =COUNTIF(included_studies!A2:A117, "=Schizophrenia") -> 0 | C2: AD | D2: =COUNTIF(included_studies!A2:A117, "AD") -> 116 | E2: Stroke | F2: =COUNTIF(included_studies!A2:A117, "Stroke") -> 0 | I2: MMSE
A3: Depression | B3: =COUNTIF(included_studies!A2:A117, "=Depression") -> 0 | C3: PD | D3: =COUNTIF(included_studies!A2:A117, "PD") -> 0 | E3: Epilepsy | F3: =COUNTIF(included_studies!A2:A117, "Epilepsy") -> 0 | I3: TMT
A4: Insomnia | B4: =COUNTIF(included_studies!A2:A117, "=Insomnia") -> 0 | C4: MCI | D4: =COUNTIF(included_studies!A2:A117, "MCI") -> 0 | E4: Mal de Débarquement Syndrome | F4: =COUNTIF(included_studies!A2:A117, "Mal de Débarquement Syndrome") -> 0 | I4: RVLT
A5: ADHD | B5: =COUNTIF(included_studies!A2:A117, "ADHD") -> 0 | C5: Dementia | D5: =COUNTIF(included_studies!A2:A117, "Dementia") -> 0 | E5: Chronic Low Back Pain | F5: =COUNTIF(included_studies!A2:A117, "=Chronic Low Back Pain") -> 0 | I5: MoCA
A6: Use Disorder | B6: =COUNTIF(included_studies!A2:A117, "Use Disorder") -> 0 | C6: MS | D6: =COUNTIF(included_studies!A2:A117, "MS") -> 0 | E6: Tinnitus | F6: =COUNTIF(included_studies!A2:A117, "=Tinnitus") -> 0 | I6: Adas-cog
A7: Bipolar Disorder | B7: =COUNTIF(included_studies!A2:A117, "=Bipolar Disorder") -> 0 | C7: Huntington’s disease | D7: =COUNTIF(included_studies!A2:A117, "Huntington’s disease") -> 0 | E7: Migraine | F7: =COUNTIF(included_studies!A2:A117, "Migraine") -> 0
A8: Anxiety | B8: =COUNTIF(included_studies!A2:A117, "Anxiety") -> 0 | C8: Glaucoma | D8: =COUNTIF(included_studies!A2:A117, "Glaucoma") -> 0 | E8: Fibromyalgia | F8: =COUNTIF(included_studies!A2:A117, "Fibromyalgia") -> 0
A9: Psychosis Spectrum Disorder | B9: =COUNTIF(included_studies!A2:A117, "Psychosis Spectrum Disorder") -> 0 | C9: MCI/Dementia | D9: =COUNTIF(included_studies!A2:A117, "MCI/Dementia") -> 0 | E9: 22q11.2 deletion syndrome | F9: =COUNTIF(included_studies!A2:A117, "22q11.2 deletion syndrome") -> 0
A10: Internalizing Psychopathologies | B10: =COUNTIF(included_studies!A2:A117, "Internalizing Psychopathologies") -> 0 | C10: Lewy Body Dementia | D10: =COUNTIF(included_studies!A2:A117, "Lewy Body Dementia") -> 0 | E10: Essential Tremor | F10: =COUNTIF(included_studies!A2:A117, "=Essential Tremor") -> 0
A11: Obsessive Compulsive Disorder | B11: =COUNTIF(included_studies!A2:A117, "Obsessive Compulsive Disorder") -> 0 | E11: Dystonic Tremor Syndromes | F11: =COUNTIF(included_studies!A2:A117, "Dystonic Tremor Syndromes") -> 0
A12: Premenstrual Dysphoric Disorder | B12: =COUNTIF(included_studies!A2:A117, "Premenstrual Dysphoric Disorder") -> 0 | E12: Spinocerebellar Ataxia | F12: =COUNTIF(included_studies!A2:A117, "=Spinocerebellar Ataxia") -> 0
E13: Ataxia | F13: =COUNTIF(included_studies!A2:A117, "Ataxia") -> 0
E14: Persistent post-concussive symptoms | F14: =COUNTIF(included_studies!A2:A117, "Persistent post-concussive symptoms") -> 0
E15: Unresponsive wakefulness syndrome | F15: =COUNTIF(included_studies!A2:A117, "Unresponsive wakefulness syndrome") -> 0
E16: Congenital Amusia | F16: =COUNTIF(included_studies!A2:A117, "Congenital Amusia") -> 0
E17: Postoperative Sleep Disturbance | F17: =COUNTIF(included_studies!A2:A117, "Postoperative Sleep Disturbance") -> 0

Sheet cog_outcomes
A1: Outcome | B1: Cognitive Domain | C1: Subdomain | D1: Scoring Direction | H1: Cognitive Domain | I1: MMSE | J1: MoCA | K1: FSIQ | L1: FAB | M1: ADAS-cog | N1: BACS | O1: RBANS | P1: BAC | Q1: MATRICS | R1: CDT | S1: TMT B-A | T1: IADL | U1: CVFT | V1: VFT | W1: LVFT | X1: Stroop | Y1: SWMT | Z1: BNT | AA1: PVF | AB1: DSB | AC1: DSF | AD1: Dual N-back | AE1: HVLT | AF1: RCFT | AG1: RAVLT | AH1: EMQ-R | AI1: CS 21 | AJ1: FNAT | AK1: MoCA MIS | AL1: WMS-IV | AM1: CVLT-SDFR | AN1: CVLT-LDFR | AO1: CVFT | AP1: DSST | AQ1: TMT A | AR1: TMT B | AS1: IVA | AT1: CPT | AU1: BART | AV1: DDT | AW1: MID | AX1: MRLT | AY1: EERT | AZ1: VWM | BA1: SDMT | BB1: PASAT | BC1: SRTT
A2: MMSE | B2: Global cognition | C2: Orientation, registration, attention, calculation, recall, language | D2: Higher = better | H2: Global Cognition | I2: 1 | J2: 1 | M2: 1 | N2: 1 | O2: 1 | P2: 1 | BD2: =SUM(I2:BC2) -> 6
A3: MoCA | B3: Global cognition | C3: Executive function, attention, memory, language, visuospatial skills, orientation | D3: Higher = better | H3: Executive Function | I3: 1 | J3: 1 | L3: 1 | N3: 1 | P3: 1 | R3: 1 | S3: 1 | T3: 1 | U3: 1 | V3: 1 | W3: 1 | X3: 1 | AA3: 1 | AD3: 1 | AI3: 1 | AO3: 1 | AR3: 1 | BD3: =SUM(I3:BC3) -> 17
A4: FSIQ | B4: Intelligence | C4: Verbal comprehension, perceptual reasoning, working memory, processing speed | D4: Higher = better | H4: Intelligence | K4: 1 | BD4: =SUM(I4:BC4) -> 1
A5: FAB | B5: Executive function | C5: Planning, inhibition, verbal fluency | D5: Higher = better | H5: Visuospatial | J5: 1 | O5: 1 | R5: 1 | AF5: 1 | BD5: =SUM(I5:BC5) -> 4
A6: ADAS-cog | B6: Global cognition | C6: Memory, language, praxis, orientation | D6: Higher = better | H6: Language | I6: 1 | J6: 1 | M6: 1 | O6: 1 | T6: 1 | U6: 1 | V6: 1 | W6: 1 | Z6: 1 | AA6: 1 | AJ6: 1 | AO6: 1 | BD6: =SUM(I6:BC6) -> 12
A7: BACS | B7: Global cognition | C7: Memory, executive function, attention, motor speed | D7: Higher = better | H7: Memory | J7: 1 | M7: 1 | N7: 1 | O7: 1 | P7: 1 | Q7: 1 | AF7: 1 | AK7: 1 | AL7: 1 | BD7: =SUM(I7:BC7) -> 9
A8: RBANS | B8: Global cognition | C8: Memory, attention, visuospatial, language | D8: Higher = better | H8: Working Memory | I8: 1 | K8: 1 | Y8: 1 | AB8: 1 | AC8: 1 | AD8: 1 | AL8: 1 | AZ8: 1 | BB8: 1 | BD8: =SUM(I8:BC8) -> 9
A9: BAC | B9: Global cognition | C9: Memory, executive function, attention, motor speed | D9: Higher = better | H9: Verbal Memory | AE9: 1 | AG9: 1 | AL9: 1 | AM9: 1 | AN9: 1 | BD9: =SUM(I9:BC9) -> 5
A10: MATRICS | B10: Neurocognition | C10: memory, attention, processing speed, social cognition | D10: Higher = better | H10: Attention | I10: 1 | N10: 1 | O10: 1 | P10: 1 | Q10: 1 | AC10: 1 | AD10: 1 | AI10: 1 | AP10: 1 | AQ10: 1 | AS10: 1 | AT10: 1 | BA10: 1 | BB10: 1 | BC10: 1 | BD10: =SUM(I10:BC10) -> 15
A11: CDT | B11: Executive / Visuospatial | C11: Planning, visuospatial construction | D11: Higher = better | H11: Processing Speed | K11: 1 | Q11: 1 | AP11: 1 | AQ11: 1 | BA11: 1 | BD11: =SUM(I11:BC11) -> 5
A12: TMT B-A | B12: Executive | C12: Cognitive flexibility / set-shifting | D12: Lower = better | H12: Inhibition | X12: 1 | BD12: =SUM(I12:BC12) -> 1
A13: IADL | B13: Functional ability | C13: Instrumental ADLs | D13: Higher = better | H13: Orientation | I13: 1 | J13: 1 | M13: 1 | BD13: =SUM(I13:BC13) -> 3
A14: Semantic Fluency (CVFT) | B14: Language / Executive | C14: Semantic memory | D14: Higher = better | H14: Decision making | AU14: 1 | AX14: 1 | BD14: =SUM(I14:BC14) -> 2
A15: VFT | B15: Language / Executive | C15: Phonemic or semantic fluency | D15: Higher = better | H15: Inhibition | L15: 1 | AS15: 1 | AT15: 1 | BD15: =SUM(I15:BC15) -> 3
A16: LVFT | B16: Language / Executive | C16: Phonemic fluency | D16: Higher = better | H16: Verbal comprehension | K16: 1 | BD16: =SUM(I16:BC16) -> 1
A17: Stroop Task | B17: Executive | C17: Cognitive control / inhibitory control | D17: Accuracy: higher = better; RT: lower = better | H17: Perceptual reasoning | K17: 1 | BD17: =SUM(I17:BC17) -> 1
A18: SWMT | B18: Working memory | C18: Short-term maintenance / retrieval | D18: Accuracy: higher = better; RT: lower = better | H18: Verbal fluency | L18: 1 | BD18: =SUM(I18:BC18) -> 1
A19: BNT | B19: Language | C19: Naming / lexical retrieval | D19: Higher = better | H19: Semantic fluency | U19: 1 | V19: 1 | AO19: 1 | BD19: =SUM(I19:BC19) -> 3
A20: PVF | B20: Language / Executive | C20: Phonemic verbal fluency | D20: Higher = better | H20: Phonemic fluency | W20: 1 | AA20: 1 | BD20: =SUM(I20:BC20) -> 2
A21: DSB (Digit Span Backward) | B21: Working memory | C21: Auditory working memory | D21: Higher = better | H21: Planning | R21: 1 | S21: 1 | BD21: =SUM(I21:BC21) -> 2
A22: DSF (Digit Span Forward) | B22: Attention / working memory | C22: Short-term auditory memory | D22: Higher = better | H22: Set-shifting | AR22: 1 | BD22: =SUM(I22:BC22) -> 1
A23: Dual N-back | B23: Working memory | C23: Verbal working memory, Visuospatial working memory updating & monitoring, executive function, attention | D23: Higher = better | H23: Subjective Memory | AH23: 1 | BD23: =SUM(I23:BC23) -> 1
A24: HVLT | B24: Verbal memory | C24: Immediate / delayed recall | D24: Higher = better | H24: Reward processing | AU24: 1 | AV24: 1 | AW24: 1 | AX24: 1 | AY24: 1 | BD24: =SUM(I24:BC24) -> 5
A25: RCFT | B25: Visuospatial / memory | C25: Copy, immediate recall, delayed recall | D25: Higher = better | H25: Total | I25: =SUM(I2:I24) -> 6 | J25: =SUM(J2:J24) -> 6 | K25: =SUM(K2:K24) -> 5 | L25: =SUM(L2:L24) -> 3 | M25: =SUM(M2:M24) -> 4 | N25: =SUM(N2:N24) -> 4 | O25: =SUM(O2:O24) -> 5 | P25: =SUM(P2:P24) -> 4 | ... BC25: =SUM(BC2:BC24) -> 1
A26: RAVLT | B26: Verbal memory | C26: Immediate / delayed recall | D26: Higher = better
A27: EMQ-R | B27: Subjective memory | C27: Everyday memory complaints | D27: Lower = better
A28: CS21 | B28: Attention / executive | C28: Sustained attention / interference control | D28: Higher = better
A29: FNAT | B29: Language / naming | C29: Action / object naming | D29: Higher = better
A30: MoCA MIS | B30: Memory | C30: Delayed recall | D30: Higher = better
A31: WMS-IV | B31: Memory | C31: Verbal & visual memory, working memory | D31: Higher = better
A32: CVLT-SDFR | B32: Verbal memory | C32: Short delay recall | D32: Higher = better
A33: CVLT-LDFR | B33: Verbal memory | C33: Long delay recall | D33: Higher = better
A34: CVFT | B34: Language / Executive | C34: Semantic fluency | D34: Higher = better
A35: DSST | B35: Attention / Processing speed | C35: Symbol substitution | D35: Higher = better
A36: TMT-A | B36: Attention / Processing speed | C36: Visual scanning | D36: Lower = better
A37: TMT-B | B37: Executive function | C37: Set-shifting | D37: Lower = better
... A48: SRTT | B48: Motor learning / attention | C48: Procedural / sequence learning | D48: Accuracy: higher = better; RT: lower = better

Sheet tACS MoCA
A1: Disorder | B1: Title | C1: Authors | D1: Year | E1: Study_ID | F1: Study_Design | G1: Blinding | H1: Intervention_group | I1: Control_group | J1: Sample_Size_PD_int | K1: Sample_Size_PD_con | L1: Sample_Size_HC | M1: N_Male_PD_int | N1: N_Female_PD_int | O1: N_Male_PD_con | P1: N_Female_PD_con | Q1: N_Male_HC | R1: N_Female_HC | S1: Handedness_PD_int | T1: Handedness_PD_con | U1: Handedness_HC | V1: Age_mean_PD_int | W1: Age_SD_PD_int | X1: Age_mean_PD_con | Y1: Age_SD_PD_con | Z1: Age_mean_HC | AA1: Age_SD_HC | AB1: Disease_duration_months_mean_int | AC1: Disease_duration_months_sd_int | AD1: Disease_duration_months_mean_con | AE1: Disease_duration_months_sd_con | AF1: Drugs_intake_mg_mean_int | AG1: Drugs_intake_mg_sd_int | AH1: Drugs_intake_mg_mean_con | AI1: Drugs_intake_mg_sd_con | AJ1: Physiotherapy_int | AK1: Physiotherapy_con | AL1: Psychotherapy_int | AM1: Psychotherapy_con | AN1: Electrode_size_cm2_stim | AO1: Electrode_size_cm2_return | AP1: Electrode_shape_stim | AQ1: Electrode_shape_return | AR1: Electrode_material | AS1: Loc_Stimulation_Electrode_int | AT1: Loc_Stimulation_Electrode_con | AU1: Loc_Return_Electrode_int | AV1: Loc_Return_Electrode_con | AW1: Frequency_Hz_int | AX1: Frequency_Hz_con | AY1: Ramping_up_sec | AZ1: Ramping_down_sec | BA1: Intensity_pp_mA | BB1: Duration_min | BC1: N_Sessions | BD1: Timepoints_of_measurement | BE1: Outcome | BF1: Outcome_category | BG1: Outcome_measure | BH1: Direction_improvement | BI1: on_off_med | BJ1: Online_Offline_stim | BK1: Mean_pre_HC | BL1: SD_pre_HC | BM1: Mean_pre_int | BN1: SD_pre_int | BO1: Mean_pre_con | BP1: SD_pre_con | BQ1: Mean_during_int | BR1: SD_during_int | BS1: Mean_during_con | BT1: SD_during_con | BU1: Mean_post_immediate_int | BV1: SD_post_immediate_int | BW1: Mean_post_immediate_con | BX1: SD_post_immediate_con | BY1: Mean_post_intermediate_int | BZ1: SD_post_intermediate_int | CA1: Mean_post_intermediate_con | CB1: SD_post_intermediate_con | CC1: Mean_post_long_int | CD1: SD_post_long_int | CE1: Mean_post_long_con | CF1: SD_post_long_con | CG1: p_value | CH1: Effect_Size | CI1: Main_finding
A2: Depression | B2: Intervention With Non-Invasive Brain Stimulation and Cognitive Training for Depressive Symptomatology Associated With Breast Cancer (ONCODEP) | C2: Salgado | D2: 2025 | E2: 44 | F2: 1 | G2: 2 | H2: tACS + CTT | I2: Sham tES + CTT | J2: -99 | K2: -99 | L2: -99 | M2: -99 | N2: -99 | O2: -99 | P2: -99 | Q2: -99 | R2: -99 | S2: 0 | T2: -99 | U2: -99 | V2: -99 | W2: -99 | X2: -99 | Y2: -99 | Z2: -99 | AA2: -99 | AB2: -99 | AC2: -99 | AD2: -99 | AE2: -99 | AF2: -99 | AG2: -99 | AH2: -99 | AI2: -99 | AJ2: 0 | AK2: 0 | AL2: 0 | AM2: 0 | AN2: 25 | AO2: 25 | AP2: 1 | AQ2: 0 | AR2: 0 | AS2: 1-DLPFC; F3 F4 | AT2: F3, F4 [half of sample] | AU2: Fpz | AV2: Fpz [half of sample], F3, Fp2 [half of sample] | AW2: 4 | AX2: Sham | AY2: 15 | AZ2: 15 | BA2: 2 | BB2: 20 | BC2: 15 | BE2: MoCA | BF2: 1 | BG2: Global cognition | BH2: 1 | BI2: -1 | BJ2: -1 | BK2: -1 | BL2: -1 | BM2: 26.083 | BN2: 2.765 | BO2: 25.933 | BP2: 2.631 | BU2: 26.652 | BV2: 2.386 | BW2: 26.933 | BX2: 2.187 | BY2: 26.913 | BZ2: 2.234 | CA2: 26.733 | CB2: 1.907
A3: AD | B3: TRanscranial AlterNating current stimulation FOR patients with mild Alzheimer’s Disease (TRANSFORM-AD): a randomized controlled clinical trial | C3: Tang, Y. | D3: 2024 | E3: 59 | F3: 1 | G3: 1 | H3: Gamma tACS | I3: Sham tACS | J3: 23 | K3: 23 | L3: -99 | M3: 7 | N3: 16 | O3: 9 | P3: 14 | Q3: -99 | R3: -99 | S3: 1 | T3: 1 | U3: -99 | V3: 68.57 | W3: 5.21 | X3: 63.7 | Y3: 6.05 | Z3: -99 | AA3: -99 | AB3: -99 | AC3: -99 | AD3: -99 | AE3: -99 | AF3: -99 | AG3: -99 | AH3: -99 | AI3: -99 | AJ3: 0 | AK3: 0 | AL3: 0 | AM3: 0 | AN3: 42.41 | AO3: 12.12 | AP3: 0 | AQ3: 0 | AR3: 2 | AS3: Fpz, Fp1, Fp2 | AT3: Fpz, Fp1, Fp2 | AU3: Mastoid region | AV3: Mastoid region | AW3: 40 | AX3: Sham | AY3: -99 | AZ3: -99 | BA3: 15 | BB3: 60 | BC3: 30 | BD3: 0,2 | BE3: MoCA | BF3: 1 | BG3: Global cognition | BH3: 1 | BI3: 1 | BJ3: 0 | BK3: -99 | BL3: -99 | BM3: 14.52 | BN3: 3.82 | BO3: 15.74 | BP3: 3.99 | BU3: 16.737 | BV3: 6.16 | BW3: 16.088 | BX3: 6.49 | BY3: 15.38 | BZ3: 6.22 | CA3: 16.89 | CB3: 7.89
A4: AD | B4: Impact of multisession 40Hz tACS on hippocampal perfusion in patients with Alzheimer’s disease | C4: Sprugnoli | D4: 2021 | E4: 63 | F4: 1 | G4: 0 | H4: tACS (3 montages combined) | I4: -99 | J4: 15 | K4: -99 | L4: -99 | M4: 9 | N4: 6 | O4: -99 | P4: -99 | Q4: -99 | R4: -99 | S4: 0 | T4: 0 | U4: -99 | V4: 72 | X4: -99 | Y4: -99 | Z4: -99 | AA4: -99 | AB4: -99 | AC4: -99 | AD4: -99 | AE4: -99 | AF4: -99 | AG4: -99 | AH4: -99 | AI4: -99 | AJ4: 0 | AK4: -99 | AL4: 0 | AM4: -99 | AN4: 3.14 | AO4: 3.14 | AP4: 1 | AQ4: 1 | AR4: 1 | AS4: P7, T7 | AT4: -99 | AU4: T8, P8 | AV4: -99 | AW4: 40 | AX4: -99 | AY4: 30 | AZ4: 30 | BA4: 4 | BB4: 60 | BC4: 10,10, 20 | BD4: 0,2 | BE4: MoCA | BF4: 1 | BG4: Global cognition | BH4: 1 | BI4: 1 | BJ4: 0 | BK4: -99 | BL4: -99 | BM4: 15.73 | BN4: 4.23 | BO4: -99 | BP4: -99 | BU4: 17.53 | BV4: 4.5 | BW4: -99 | BX4: -99 | CG4: 0.05 | CH4: 0.41
A5: PD | B5: Personalized transcranial alternating current stimulation (tACS) and physical therapy to treat motor and cognitive symptoms in Parkinson's disease: A randomized cross-over trial | C5: DelFelice | D5: 2019 | E5: 97 | F5: 0 | G5: 1 | H5: tACS | I5: tRNS (active sham) | J5: 15 | K5: 15 | L5: -99 | M5: 9 | N5: 6 | O5: 9 | P5: 6 | Q5: -99 | R5: -99 | S5: 0 | T5: 0 | U5: -99 | V5: 69 | W5: 6.3 | X5: 69 | Y5: 6.3 | Z5: -99 | AA5: -99 | AB5: 6.3 | AC5: 4.8 | AD5: 6.3 | AE5: 4.8 | AF5: 528.5 | AG5: 290 | AH5: 528.5 | AI5: 290 | AJ5: 1 | AK5: 1 | AL5: 0 | AM5: 0 | AN5: 35 | AO5: 35 | AP5: 0 | AQ5: 0 | AR5: 0 | AS5: FC1 [1], FC5 [2], C3 [2], CP5 [3], Pz [1], F3 [1], C4 [5] | AT5: Ipsilateral mastoid | AU5: FC1 [1], FC5 [2], C3 [2], CP5 [3], Pz [1], F3 [1], C4 [5] | AV5: Ipsilateral mastoid | AW5: 30 Hz [6], 4 Hz [11] | AX5: Sham | AY5: -99 | AZ5: -99 | BA5: 2 | BB5: 30 | BC5: 10 | BD5: 0,2,8 | BE5: MoCA | BF5: 1 | BG5: Global cognition | BH5: 1 | BI5: 0 | BJ5: 0 | BK5: -99 | BL5: -99 | BM5: 24,79 | BN5: -99 | BO5: 23,71 | BP5: -99 | BU5: 22,71 | BV5: -99 | BW5: 24,79 | BX5: -99 | BY5: 26,5 | BZ5: -99 | CA5: 23 | CB5: -99
A6: PD | B6: Common and specific effects in brain oscillations and motor symptoms of tDCS and tACS in Parkinson’s disease | C6: Liu J | D6: 2025 | E6: 103 | F6: 1 | G6: 1 | H6: tACS | I6: Sham | J6: 20 | K6: 20 | L6: -99 | M6: 14 | N6: 6 | O6: 13 | P6: 7 | Q6: -99 | R6: -99 | S6: 1 | T6: 1 | U6: -99 | V6: 59.25 | W6: 5.95 | X6: 62.25 | Y6: 6.87 | Z6: -1 | AA6: -1 | AB6: 4.5 | AC6: 3.03 | AD6: 3.39 | AE6: 2.83 | AF6: 315 | AG6: 118.21 | AH6: 300 | AI6: 119.21 | AJ6: 0 | AK6: 0 | AL6: 0 | AM6: 0 | AN6: 3.14 | AO6: 3.14 | AP6: 1 | AQ6: 1 | AR6: 1 | AS6: C3 | AT6: C3 | AU6: Right shoulder | AV6: C4 | AW6: 40 Hz | AX6: Sham | AY6: 10 | AZ6: 10 | BA6: 2 | BB6: 20 | BC6: 1 | BD6: 0,2 | BE6: MoCA | BF6: 1 | BG6: Global cognition | BH6: 1 | BI6: 1 | BJ6: 0 | BK6: -99 | BL6: -99 | BM6: 20.5 | BN6: 5.27 | BO6: 19.05 | BP6: 5.64 | BU6: -99 | BV6: -99 | BW6: -99 | BX6: -99
A7: Fibromyalgia | B7: Beyond physiotherapy and pharmacological treatment for fibromyalgia syndrome: tailored tACS as a new therapeutic tool | C7: Bernardi | D7: 2021 | E7: 127 | F7: 0 | G7: 1 | H7: tACS | I7: RNS | J7: 15 | K7: 15 | L7: -99 | M7: 2 | N7: 13 | O7: 2 | P7: 13 | Q7: -99 | R7: -99 | S7: 0 | T7: 0 | U7: -99 | V7: 53.07 | W7: 4.18 | X7: 53.07 | Y7: 4.18 | Z7: -99 | AA7: -99 | AJ7: 1 | AK7: 1 | AL7: 0 | AM7: 0 | AN7: 35 | AO7: 35 | AP7: 1 | AQ7: 1 | AR7: 0 | AS7: F3 [1], C3 [3], Cp5 [4], C4/Cp2 [1], C3/Cp5 [1], Cz-Fz [1], Cz-Pz [1], Cz [2], F4 [1] | AT7: Ipsilateral mastoid | AU7: F3 [1], C3 [3], Cp5 [4], C4/Cp2 [1], C3/Cp5 [1], Cz-Fz [1], Cz-Pz [1], Cz [2], F4 [1] | AV7: Ipsilateral mastoid | AW7: 30 Hz [11], 4 Hz [4] | AX7: 0-99 | AY7: -99 | AZ7: -99 | BA7: 2 | BB7: 30 | BC7: 10 | BE7: MoCA | BF7: 1 | BG7: Global cognition | BH7: 1 | BI7: 1 | BJ7: 0

Sheet tACS RAVLT
A1: Disorder | B1: Title | C1: Authors | D1: Year | E1: Study_ID | F1: Study_Design | G1: Blinding | H1: Intervention_group | I1: Control_group | J1: Sample_Size_PD_int | K1: Sample_Size_PD_con | L1: Sample_Size_HC | M1: N_Male_PD_int | N1: N_Female_PD_int | O1: N_Male_PD_con | P1: N_Female_PD_con | Q1: N_Male_HC | R1: N_Female_HC | S1: Handedness_PD_int | T1: Handedness_PD_con | U1: Handedness_HC | V1: Age_mean_PD_int | W1: Age_SD_PD_int | X1: Age_mean_PD_con | Y1: Age_SD_PD_con | Z1: Age_mean_HC | AA1: Age_SD_HC | AB1: Disease_duration_months_mean_int | AC1: Disease_duration_months_sd_int | AD1: Disease_duration_months_mean_con | AE1: Disease_duration_months_sd_con | AF1: Drugs_intake_mg_mean_int | AG1: Drugs_intake_mg_sd_int | AH1: Drugs_intake_mg_mean_con | AI1: Drugs_intake_mg_sd_con | AJ1: Physiotherapy_int | AK1: Physiotherapy_con | AL1: Psychotherapy_int | AM1: Psychotherapy_con | AN1: Electrode_size_cm2_stim | AO1: Electrode_size_cm2_return | AP1: Electrode_shape_stim | AQ1: Electrode_shape_return | AR1: Electrode_material | AS1: Loc_Stimulation_Electrode_int | AT1: Loc_Stimulation_Electrode_con | AU1: Loc_Return_Electrode_int | AV1: Loc_Return_Electrode_con | AW1: Frequency_Hz_int | AX1: Frequency_Hz_con | AY1: Ramping_up_sec | AZ1: Ramping_down_sec | BA1: Intensity_pp_mA | BB1: Duration_min | BC1: N_Sessions | BD1: Timepoints_of_measurement | BE1: Outcome | BF1: Outcome_category | BG1: Outcome_measure | BH1: Direction_improvement | BI1: on_off_med | BJ1: Online_Offline_stim | BK1: Mean_pre_HC | BL1: SD_pre_HC | BM1: Mean_pre_int | BN1: SD_pre_int | BO1: Mean_pre_con | BP1: SD_pre_con | BQ1: Mean_during_int | BR1: SD_during_int | BS1: Mean_during_con | BT1: SD_during_con | BU1: Mean_post_immediate_int | BV1: SD_post_immediate_int | BW1: Mean_post_immediate_con | BX1: SD_post_immediate_con | BY1: Mean_post_intermediate_int | BZ1: SD_post_intermediate_int | CA1: Mean_post_intermediate_con | CB1: SD_post_intermediate_con | CC1: Mean_post_long_int | CD1: SD_post_long_int | CE1: Mean_post_long_con | CF1: SD_post_long_con | CG1: p_value | CH1: Effect_Size | CI1: Main_finding | CJ1: Mean change | CK1: SD_change | CL1: Mean change | CM1: SD_change
A2: AD | B2: TRanscranial AlterNating current stimulation FOR patients with mild Alzheimer’s Disease (TRANSFORM-AD): a randomized controlled clinical trial | C2: Tang, Y. | D2: 2024 | E2: 59 | F2: 1 | G2: 1 | H2: 40 Hz Gamma tACS | I2: Sham tACS | J2: 23 | K2: 23 | L2: -999 | M2: 7 | N2: 16 | O2: 9 | P2: 14 | Q2: -999 | R2: -999 | S2: 1 | T2: 1 | U2: -999 | V2: 68.57 | W2: 5.21 | X2: 63.7 | Y2: 6.05 | Z2: -999 | AA2: -999 | AB2: -999 | AC2: -999 | AD2: -999 | AE2: -999 | AF2: -999 | AG2: -999 | AH2: -999 | AI2: -999 | AJ2: 0 | AK2: 0 | AL2: 0 | AM2: 0 | AN2: 42.41 | AO2: 12.12 | AP2: 0 | AQ2: 0 | AR2: 2 | AS2: Fpz, Fp1, Fp2 | AT2: Fpz, Fp1, Fp2 | AU2: Mastoid region | AV2: Mastoid region | AW2: 40 | AX2: Sham | AY2: -99 | AZ2: -99 | BA2: 15 | BB2: 60 | BC2: 30 | BD2: 0,2 | BE2: RAVLT-IR | BF2: 1 | BG2: Verbal Memory | BH2: 1 | BI2: 1 | BJ2: 0 | BK2: -999 | BL2: -999 | BM2: 14.78 | BN2: 5.95 | BO2: 14.83 | BP2: 4.54 | BU2: 16.43 | BV2: 7.31 | BW2: 13.48 | BX2: 4.82 | BY2: 16.21 | BZ2: 7.36 | CA2: 14.1 | CB2: 4.68
BE3: RAVLT-DR | BF3: 1 | BG3: Verbal Memory | BH3: 1 | BM3: 1.04 | BN3: 1.3 | BO3: 1 | BP3: 1.21 | BU3: 2.91 | BV3: 4.11 | BW3: 0.87 | BX3: 1.42 | BY3: 3.29 | BZ3: 2.05 | CA3: 1.05 | CB3: 1.64
BE4: RAVLT-RR | BF4: 1 | BG4: Verbal Memory | BH4: 1 | BM4: 6.09 | BN4: 3.48 | BO4: 5.65 | BP4: 2.98 | BU4: 6.57 | BV4: 3.82 | BW4: 5.43 | BX4: 3.95 | BY4: 5 | BZ4: 3.61 | CA4: 5.65 | CB4: 2.96
A5: AD | B5: Increasing Brain Gamma Activity Improves Episodic Memory and Restores Cholinergic Dysfunction in Alzheimer’s Disease | C5: Benussi | D5: 2022 | E5: 61 | F5: 0 | G5: 1 | H5: Gamma tACS | I5: Sham tACS | J5: 60 | K5: 60 | L5: -999 | M5: 29 | N5: 31 | O5: 29 | P5: 31 | Q5: -999 | R5: -999 | S5: 0 | T5: 0 | U5: -999 | V5: 72.3 | W5: 7 | X5: 72.3 | Y5: 7 | Z5: -999 | AA5: -999 | AB5: 37.2 | AC5: 28.8 | AD5: 37.2 | AE5: 28.8 | AF5: -999 | AG5: -999 | AH5: -999 | AI5: -999 | AJ5: 0 | AK5: 0 | AL5: 0 | AM5: -999 | AN5: 33 | AO5: 33 | AP5: 0 | AQ5: 0 | AR5: 0 | AS5: Pz | AT5: Pz | AU5: Right deltoid muscle | AV5: Right deltoid muscle | AW5: 40 | AX5: Sham | AY5: -999 | AZ5: -999 | BA5: 3 | BB5: 60 | BC5: 1 | BD5: 0, 2 | BE5: RAVLT-IR | BF5: 1 | BG5: Verbal Memory | BH5: 1 | BI5: 1 | BJ5: 0 | BK5: -999 | BL5: -999 | BM5: 18.4 | BN5: 6.9 | BO5: 20.3 | BP5: 6.5 | BU5: 25.6 | BV5: 8.4 | BW5: 18.7 | BX5: 6.3
BE6: RAVLT-DR | BF6: 1 | BG6: Verbal Memory | BH6: 1 | BM6: 1.5 | BN6: 1.4 | BO6: 1.4 | BP6: 1.5 | BU6: 2.5 | BV6: 2.1 | BW6: 1 | BX6: 1.2
BE7: RAVLT-RR | BF7: 1 | BG7: Verbal Memory | BH7: 1 | BM7: -999 | BN7: -999 | BO7: -999 | BP7: -999 | BU7: -999 | BV7: -999 | BW7: -999 | BX7: -999
A8: AD | B8: Exposure to gamma tACS in Alzheimer’s disease: A randomized, double-blind, sham-controlled, crossover, pilot study | C8: Benussi | D8: 2021 | E8: 65 | F8: 0 | G8: 1 | H8: Gamma tACS | I8: Sham tACS | J8: 20 | K8: 20 | L8: -999 | M8: 10 | N8: 10 | O8: 10 | P8: 10 | Q8: -999 | R8: -999 | S8: 0 | T8: 0 | U8: -999 | V8: 71.9 | W8: 7 | X8: 71.9 | Y8: 7 | Z8: -999 | AA8: -999 | AB8: 33.6 | AC8: 22.8 | AD8: 33.6 | AE8: 22.8 | AF8: -999 | AG8: -999 | AH8: -999 | AI8: -999 | AJ8: 0 | AK8: 0 | AL8: 0 | AM8: -999 | AN8: 33 | AO8: 33 | AP8: 0 | AQ8: 0 | AR8: 0 | AS8: Pz | AT8: Pz | AU8: Right deltoid muscle | AV8: Right deltoid muscle | AW8: 40 | AX8: Sham | AY8: -999 | AZ8: -999 | BA8: 3 | BB8: 60 | BC8: 1 | BD8: 0,2 | BE8: RAVLT-IR | BF8: 1 | BG8: Verbal Memory | BH8: 1 | BI8: 1 | BJ8: 0 | BK8: -999 | BL8: -999 | BM8: 18.9 | BN8: 8.4 | BO8: 19.5 | BP8: 6.6 | BU8: 25.1 | BV8: 8.7 | BW8: 19.4 | BX8: 6.8
BE9: RAVLT-DR | BF9: 2 | BG9: Verbal Memory | BH9: 1 | BM9: 1.7 | BN9: 1.4 | BO9: 1.5 | BP9: 1.5 | BU9: 2.8 | BV9: 1.9 | BW9: 1.6 | BX9: 1.5
BE10: RAVLT-RR | BF10: 3 | BG10: Verbal Memory | BH10: 1 | BM10: -999 | BN10: -999 | BO10: -999 | BP10: -999 | BU10: -999 | BV10: -999 | BW10: -999 | BX10: -999
A11: Lewy Body Dementia | B11: Alpha tACS Improves Cognition and Modulates Neurotransmission in Dementia with Lewy Bodies | C11: Benussi | D11: 2024 | E11: 57 | F11: 0 | G11: 1 | H11: Alpha tACS | I11: Sham tACS | J11: 14 | K11: 14 | L11: -999 | M11: 7 | N11: 7 | O11: 7 | P11: 7 | Q11: -999 | R11: -999 | S11: 0 | T11: 0 | U11: -999 | V11: 73.1 | W11: 5.9 | X11: 73.1 | Y11: 5.9 | Z11: -999 | AA11: -999 | AB11: 51.6 | AC11: 27.6 | AD11: 51.6 | AE11: 27.6 | AF11: -999 | AG11: -999 | AH11: -999 | AI11: -999 | AJ11: 0 | AK11: 0 | AL11: 0 | AM11: -999 | AN11: 33 | AO11: 33 | AP11: 0 | AQ11: 0 | AR11: 0 | AS11: Oz | AT11: Oz | AU11: Right deltoid muscle | AV11: Right deltoid muscle | AW11: 12 | AX11: Sham | AY11: -999 | AZ11: -999 | BA11: 3 | BB11: 60 | BC11: 1 | BD11: 0,2 | BE11: RAVLT-IR | BF11: 1 | BG11: Verbal Memory | BH11: 1 | BI11: 1 | BJ11: 0 | BK11: -999 | BL11: -999 | CJ11: 4.5 | CK11: 4.93 | CL11: 1.9 | CM11: 2.86
BE12: RAVLT-DR | BF12: 1 | BG12: Verbal Memory | BH12: 1 | CJ12: 0.1 | CK12: 2.34 | CL12: -0.1 | CM12: 0.26
BE13: RAVLT-RR | BF13: 1 | BG13: Verbal Memory | BH13: 1
A14: MS | B14: The effects of gamma-tACS on cognitive impairment in multiple sclerosis: Arandomized, double-blind, sham-controlled,pilot study | C14: Ferrazzano | D14: 2025 | E14: 93 | F14: 0 | G14: 1 | H14: Gamma tACS | I14: Sham tACS | J14: 11 | K14: 11 | L14: -999 | M14: 2 | N14: 9 | O14: 2 | P14: 9 | Q14: -999 | R14: -999 | S14: 0 | T14: 0 | U14: -999 | Z14: -999 | AA14: -999 | AJ14: 0 | AK14: 0 | AL14: 0 | AM14: -999 | AN14: 25 | AO14: 25 | AP14: 0 | AQ14: 0 | AR14: 0 | AS14: Pz | AT14: Pz | AU14: Right shoulder | AV14: Right shoulder | AW14: 40 | AX14: Sham | AY14: 3 | AZ14: 3 | BA14: 1.5 | BB14: 30 | BC14: 1 | BD14: 0,1,2 | BE14: RAVLT-IR | BF14: 1 | BG14: Verbal Memory | BH14: 1 | BI14: 1 | BJ14: 0, 1 | BK14: -999 | BL14: -999 | BM14: 34.8 | BN14: 7.95 | BO14: 41.4 | BP14: 8.63 | BQ14: 49.9 | BR14: 14.4 | BS14: 37.7 | BT14: 12.3 | BU14: 35.2 | BV14: 10.5 | BW14: 36.3 | BX14: 12.6
A15: AD | B15: Home-Based Gamma Transcranial Alternating Current Stimulation in Patients With Alzheimer Disease - A Randomized Clinical Trial | C15: Cantoni | D15: 2029 | F15: 1 | G15: 1 | H15: 40 Hz Gamma tACS (home-based) | I15: Sham tACS | J15: 26 | K15: 24 | L15: -99 | M15: 13 | N15: 13 | O15: 12 | P15: 12 | Q15: -99 | R15: -99 | S15: -99 | T15: -99 | U15: -99 | V15: 66.4 | W15: 7.1 | X15: 63.8 | Y15: 8.5 | Z15: -99 | AA15: -99 | AB15: -99 | AC15: -99 | AD15: -99 | AE15: -99 | AF15: -99 | AG15: -99 | AH15: -99 | AI15: -99 | AJ15: 0 | AK15: 0 | AL15: 0 | AM15: 0 | AN15: 33 | AO15: 33 | AP15: 0 | AQ15: 0 | AR15: 0 | AS15: Pz | AT15: Pz | AU15: Right deltoid muscle | AV15: Right deltoid muscle | AW15: 40 | AX15: Sham | AY15: -99 | AZ15: -99 | BA15: 3 | BB15: 60 | BC15: 40 | BD15: 0, 2 | BE15: RAVLT-IR | BF15: 2 | BG15: Verbal Memory | BH15: 1 | BK15: -99 | BL15: -99 | BM15: 22.7 | BN15: 10.1 | BO15: 20.4 | BP15: 8.5 | BU15: 23.3 | BV15: 9.7 | BW15: 17.3 | BX15: 6.1
BE16: RAVLT-DR | BF16: 3 | BG16: Verbal Memory | BH16: 1 | BM16: 2 | BN16: 2 | BO16: 1.5 | BP16: 2.1 | BU16: 2.1 | BV16: 2.5 | BW16: 0.8 | BX16: 1.3

Sheet tACS ADAS-Cog
A1: Disorder | B1: Title | C1: Authors | D1: Year | E1: Study_ID | F1: Study_Design | G1: Blinding | H1: Intervention_group | I1: Control_group | J1: Sample_Size_PD_int | K1: Sample_Size_PD_con | L1: Sample_Size_HC | M1: N_Male_PD_int | N1: N_Female_PD_int | O1: N_Male_PD_con | P1: N_Female_PD_con | Q1: N_Male_HC | R1: N_Female_HC | S1: Handedness_PD_int | T1: Handedness_PD_con | U1: Handedness_HC | V1: Age_mean_PD_int | W1: Age_SD_PD_int | X1: Age_mean_PD_con | Y1: Age_SD_PD_con | Z1: Age_mean_HC | AA1: Age_SD_HC | AB1: Disease_duration_months_mean_int | AC1: Disease_duration_months_sd_int | AD1: Disease_duration_months_mean_con | AE1: Disease_duration_months_sd_con | AF1: Drugs_intake_mg_mean_int | AG1: Drugs_intake_mg_sd_int | AH1: Drugs_intake_mg_mean_con | AI1: Drugs_intake_mg_sd_con | AJ1: Physiotherapy_int | AK1: Physiotherapy_con | AL1: Psychotherapy_int | AM1: Psychotherapy_con | AN1: Electrode_size_cm2_stim | AO1: Electrode_size_cm2_return | AP1: Electrode_shape_stim | AQ1: Electrode_shape_return | AR1: Electrode_material | AS1: Loc_Stimulation_Electrode_int | AT1: Loc_Stimulation_Electrode_con | AU1: Loc_Return_Electrode_int | AV1: Loc_Return_Electrode_con | AW1: Frequency_Hz_int | AX1: Frequency_Hz_con | AY1: Ramping_up_sec | AZ1: Ramping_down_sec | BA1: Intensity_pp_mA | BB1: Duration_min | BC1: N_Sessions | BD1: Timepoints_of_measurement | BE1: Outcome | BF1: Outcome_category | BG1: Outcome_measure | BH1: Direction_improvement | BI1: on_off_med | BJ1: Online_Offline_stim | BK1: Mean_pre_HC | BL1: SD_pre_HC | BM1: Mean_pre_int | BN1: SD_pre_int | BO1: Mean_pre_con | BP1: SD_pre_con | BQ1: Mean_during_int | BR1: SD_during_int | BS1: Mean_during_con | BT1: SD_during_con | BU1: Mean_post_immediate_int | BV1: SD_post_immediate_int | BW1: Mean_post_immediate_con | BX1: SD_post_immediate_con | BY1: Mean_post_intermediate_int | BZ1: SD_post_intermediate_int | CA1: Mean_post_intermediate_con | CB1: SD_post_intermediate_con | CC1: Mean_post_long_int | CD1: SD_post_long_int | CE1: Mean_post_long_con | CF1: SD_post_long_con | CG1: p_value | CH1: Effect_Size | CI1: Main_finding
A2: AD | B2: TRanscranial AlterNating current stimulation FOR patients with mild Alzheimer’s Disease (TRANSFORM-AD): a randomized controlled clinical trial | C2: Tang, Y. | D2: 2024 | E2: 59 | F2: 1 | G2: 1 | H2: 40 Hz Gamma tACS | I2: Sham tACS | J2: 23 | K2: 23 | L2: -999 | M2: 7 | N2: 16 | O2: 9 | P2: 14 | Q2: -999 | R2: -999 | S2: 1 | T2: 1 | U2: -999 | V2: 68.57 | W2: 5.21 | X2: 63.7 | Y2: 6.05 | Z2: -999 | AA2: -999 | AB2: -999 | AC2: -999 | AD2: -999 | AE2: -999 | AF2: -999 | AG2: -999 | AH2: -999 | AI2: -999 | AJ2: 0 | AK2: 0 | AL2: 0 | AM2: 0 | AN2: 4.45 x 9.53 | AO2: 3.18 x 3.81 | AP2: 0 | AQ2: 0 | AR2: 2 | AS2: Fpz, Fp1, Fp2 | AT2: Fpz, Fp1, Fp2 | AU2: Mastoid region | AV2: Mastoid region | AW2: 40 | AX2: Sham | AY2: -99 | AZ2: -99 | BA2: 15 | BB2: 60 | BC2: 30 | BD2: 0,2 | BE2: MMSE | BF2: 1 | BG2: Global Cognition | BH2: 1 | BI2: 1 | BJ2: 0 | BK2: -999 | BL2: -999 | BM2: 19.43 | BN2: 3.33 | BO2: 20.78 | BP2: 3.04 | BU2: 22.43 | BV2: 7.11 | BW2: 20.82 | BX2: 7.11 | BY2: 20.47 | BZ2: 7.09 | CA2: 20.94 | CB2: 7.92
A3: AD | B3: Effects of 40 Hz transcranial alternating current stimulation (tACS) on cognitive functions of patients with Alzheimer’s disease: a randomised, doubleblind, sham-controlled clinical trial | C3: Zhou | D3: 2022 | E3: 63 | F3: 1 | G3: 1 | H3: 40 Hz Gamma tACS | I3: Sham tACS | J3: 23 | K3: 27 | L3: -999 | M3: 8 | N3: 15 | O3: 6 | P3: 21 | Q3: -999 | R3: -999 | S3: 0 | T3: 0 | U3: -999 | V3: 76.95 | W3: 1.28 | X3: 75.78 | Y3: 1.26 | Z3: -999 | AA3: -999 | AB3: 51.84 | AC3: 4.56 | AD3: 49.44 | AE3: 3.36 | AF3: -999 | AG3: -999 | AH3: -999 | AI3: -999 | AJ3: 0 | AK3: 0 | AL3: 0 | AM3: 0 | AN3: 4 x 4 | AO3: 4 x 4 | AP3: 0 | AQ3: 0 | AR3: 0 | AS3: Temporal lobes | AT3: Temporal lobes | AU3: Temporal lobes | AV3: Temporal lobes | AW3: 40 | AX3: Sham | AY3: -999 | AZ3: -999 | BA3: 2 | BB3: 20 | BC3: 30 | BD3: 0, 2, 12 | BE3: MMSE | BF3: 1 | BG3: Global Cognition | BH3: 1 | BI3: -999 | BJ3: -999 | BK3: -999 | BL3: -999 | BM3: 16.26 | BN3: 0.94 | BO3: 17.26 | BP3: 0.88 | BU3: 20.17 | BV3: 2.75 | BW3: 18.7 | BX3: 2.25 | BY3: 19.6 | BZ3: 2.54 | CA3: 18.96 | CB3: 2.02
A5: AD | B5: TRanscranial AlterNating current stimulation FOR patients with mild Alzheimer’s Disease (TRANSFORM-AD): a randomized controlled clinical trial | C5: Tang, Y. | D5: 2024 | E5: 59 | F5: 1 | G5: 1 | H5: 40 Hz Gamma tACS | I5: Sham tACS | J5: 23 | K5: 23 | L5: -999 | M5: 7 | N5: 16 | O5: 9 | P5: 14 | Q5: -999 | R5: -999 | S5: 1 | T5: 1 | U5: -999 | V5: 68.57 | W5: 5.21 | X5: 63.7 | Y5: 6.05 | Z5: -999 | AA5: -999 | AB5: -999 | AC5: -999 | AD5: -999 | AE5: -999 | AF5: -999 | AG5: -999 | AH5: -999 | AI5: -999 | AJ5: 0 | AK5: 0 | AL5: 0 | AM5: 0 | AN5: 4.45 x 9.53 | AO5: 3.18 x 3.81 | AP5: 0 | AQ5: 0 | AR5: 2 | AS5: Fpz, Fp1, Fp2 | AT5: Fpz, Fp1, Fp2 | AU5: Mastoid region | AV5: Mastoid region | AW5: 40 | AX5: Sham | AY5: -99 | AZ5: -99 | BA5: 15 | BB5: 60 | BC5: 30 | BD5: 0,2 | BE5: ADAS-cog 11-item | BF5: 1 | BG5: Global Cognition | BH5: 1 | BI5: 1 | BJ5: 0 | BK5: -999 | BL5: -999 | BM5: 18.22 | BN5: 5.92 | BO5: 17.3 | BP5: 5.98 | BU5: 16.57 | BV5: 7.9 | BW5: 17.43 | BX5: 8.45
A6: AD | B6: Effects of 40 Hz transcranial alternating current stimulation (tACS) on cognitive functions of patients with Alzheimer’s disease: a randomised, doubleblind, sham-controlled clinical trial | C6: Zhou | D6: 2022 | E6: 63 | F6: 1 | G6: 1 | H6: 40 Hz Gamma tACS | I6: Sham tACS | J6: 23 | K6: 27 | L6: -999 | M6: 8 | N6: 15 | O6: 6 | P6: 21 | Q6: -999 | R6: -999 | S6: 0 | T6: 0 | U6: -999 | V6: 76.95 | W6: 1.28 | X6: 75.78 | Y6: 1.26 | Z6: -999 | AA6: -999 | AB6: 51.84 | AC6: 4.56 | AD6: 49.44 | AE6: 3.36 | AF6: -999 | AG6: -999 | AH6: -999 | AI6: -999 | AJ6: 0 | AK6: 0 | AL6: 0 | AM6: 0 | AN6: 4 x 4 | AO6: 4 x 4 | AP6: 0 | AQ6: 0 | AR6: 0 | AS6: Temporal lobes | AT6: Temporal lobes | AU6: Temporal lobes | AV6: Temporal lobes | AW6: 40 | AX6: Sham | AY6: -999 | AZ6: -999 | BA6: 2 | BB6: 20 | BC6: 30 | BD6: 0, 2, 12 | BE6: ADAS-cog | BF6: 1 | BG6: Global Cognition | BH6: 1 | BI6: -999 | BJ6: -999 | BK6: -999 | BL6: -999 | BM6: 30.69 | BN6: 3.95 | BO6: 29.82 | BP6: 5.75 | BU6: 23.53 | BV6: 4.17 | BW6: 29.2 | BX6: 6.09
A7: AD | B7: Home-Based Gamma Transcranial Alternating Current Stimulation in Patients With Alzheimer Disease - A Randomized Clinical Trial | C7: Cantoni | D7: 2025 | F7: 0 | G7: 1 | H7: 40 Hz Gamma tACS (home-based) | I7: Sham tACS | J7: 26 | K7: 24 | L7: -99 | M7: 13 | N7: 13 | O7: 12 | P7: 12 | Q7: -99 | R7: -99 | S7: -99 | T7: -99 | U7: -99 | V7: 66.4 | W7: 7.1 | X7: 63.8 | Y7: 8.5 | Z7: -99 | AA7: -99 | AB7: -99 | AC7: -99 | AD7: -99 | AE7: -99 | AF7: -99 | AG7: -99 | AH7: -99 | AI7: -99 | AJ7: 0 | AK7: 0 | AL7: 0 | AM7: 0 | AN7: 33 | AO7: 33 | AP7: 0 | AQ7: 0 | AR7: 0 | AS7: Pz | AT7: Pz | AU7: Right deltoid muscle | AV7: Right deltoid muscle | AW7: 40 | AX7: Sham | AY7: -99 | AZ7: -99 | BA7: 3 | BB7: 60 | BC7: 40 | BD7: 0, 2 | BE7: ADAS-cog 13-item | BF7: 1 | BG7: Global Cognition | BH7: 1 | BK7: -99 | BL7: -99 | BM7: 17.9 | BN7: 5.4 | BO7: 17.8 | BP7: 4.7 | BU7: 15.4 | BV7: 5.4 | BW7: 19.6 | BX7: 4.4
A8: Dementia | B8: Cognitive and Neuropsychiatric Effects of 40 Hz tACS Simultaneously with Cognitive Exercises for Dementia: A Randomized, Crossover, Double-Blind, Sham-Controlled Study | C8: Uehara | D8: 2025a | E8: 69 | F8: 0 | G8: 1 | H8: 40 Hz tACS | I8: Sham tACS | J8: 42 | K8: 42 | L8: -99 | M8: -99 | N8: -99 | O8: -99 | P8: -99 | Q8: -99 | R8: -99 | U8: -99 | V8: 72.9 | W8: 8.6 | X8: 76.3 | Y8: 9.3 | Z8: -99 | AA8: -99 | AB8: -99 | AC8: -99 | AD8: -99 | AE8: -99 | AF8: -99 | AG8: -99 | AH8: -99 | AI8: -99 | AJ8: 0 | AK8: 0 | AL8: 0 | AM8: 0 | AN8: -99 | AO8: -99 | AP8: -99 | AQ8: -99 | AR8: 0 | AS8: F3 | AT8: F3 | AU8: Contralateral supraorbital area. | AV8: Contralateral supraorbital area. | AW8: 40 | AX8: Sham | AY8: -99 | AZ8: -99 | BA8: 1.5 | BB8: 60 | BC8: 20 | BD8: 0, 6 | BE8: ADAS-cog | BF8: 2 | BG8: Global Cognition | BH8: 2 | BI8: -99 | BJ8: -99 | BK8: -99 | BL8: -99 | BM8: 22.17 | BN8: 8.93 | BO8: 21.37 | BP8: 9.7 | BU8: 20.32 | BV8: 8.45 | BW8: 20.23 | BX8: 7.99

Sheet Study Table
A1: Study ID | B1: Title | C1: Methods | D1: Participants | E1: Interventions | F1: Cognitive Outcomes | G1: Notes | H1: Intensity | I1: N Sessions | J1: Duration/session | K1: MoCA | L1: RAVL | M1: ADAS-cog
A2: Tang et al., 2024 | B2: TRanscranial AlterNating current stimulation FOR patients with mild Alzheimer’s Disease (TRANSFORM-AD): a randomized controlled clinical trial | C2: Parallel-group, double-blind RCT 1:1 computer-generated randomization; allocation concealed via sealed opaque envelopes; outcome assessprs blinded; follow-up 3 months; Xuanwu Hospital, Capital Medical University (China) | D2: N = 46 (23 active, 23 sham); mean age 68.57 ± 5.21 years (active), mean age 683.7 ± 6.05 years (sham) ; 65% female; mild AD (NIA-AA criteria); stable cholinesterase inhibitors > 6 weeks; exclusion: major psychiatric and medical illness, epilepsy | E2: Active: 40 Hz tACS, 15 mA, 60 min/session over 15 days (twice daily); hospital-based administration; Comparator: sham stimulation | F2: Primary: ADAS-Cog 11-item scale (baseline to post-intervention) Secondary: MoCA, RAVLT (IR, DR, RR) | G2: Trial Registration: NCT 03920826; funded by the National Natural Science Foundation of China | H2: ≥ 2mA | I2: ≥10 | J2: ≥20 minutes
A3: Benussi et al., 2022 | B3: Increasing Brain Gamma Activity Improves Episodic Memory and Restores Cholinergic Dysfunction in Alzheimer’s Disease | C3: Sham-controlled, double-blind crossover study; 1:1 computer-assisted block randomization; outcome assessors and participants blinded; Neurology Unit, Department of Clinical and Experimental Sciences, University of Brescia (Italy) | D3: N = 60, mean age 72.3 ± 7 years; 51.7% female; AD diagnosis; mean disease duration 3.1 ± 2.4 years; CSF ≤ 600 ng/L and tau≥400 ng/L or positive PET scan; exclusion: history of TBI and medical illness other than AD | E3: Active: 40 Hz tACS,3 mA, single 60 min session; stimulation inverted after 1 week; Comparator: sham stimulation | F3: Primary: RAVLT (Total Recall + DR) Secondary: FNAT | G3: Trial Registration: NCT04842955; Researchers have pending patent on the use of noninvasive brain stimulation to increase memory functions in patients with AD. | H3: ≥ 2mA | J3: ≥20 minutes
A4: Benussi et al., 2021 | B4: Exposure to gamma tACS in Alzheimer’s disease: A randomized, double-blind, sham-controlled, crossover, pilot study | C4: Sham-controlled, double-blind crossover study; 1:1 computer-assisted block randomization; outcome assessors and participants blinded; Neurology Unit, Department of Clinical and Experimental Sciences, University of Brescia (Italy) | D4: N = 20, mean age 71.9 ± 7 years, 50% female; AD diagnosis, mean duration 33.6 ± 22.8 years; CSF ≤ 600 ng/L and tau≥400 ng/L or positive PET scan; exclusion: history of TBI and medical illness other than AD; | E4: Active: 40 Hz tACS,3 mA, single 60 min session; stimulation inverted after 1 week; Comparator: sham stimulation | F4: Primary: RAVLT (IR + DR), FNAT | G4: Trial Registration: NCT04515433 | H4: ≥ 2mA | J4: ≥20 minutes
A5: Benussi et al., 2024 | B5: Alpha tACS Improves Cognition and Modulates Neurotransmission in Dementia with Lewy Bodies | C5: Sham-controlled, double-blind crossover study; 1:1 computer-assisted block randomization; outcome assessors and participants blinded; Neurology Unit, Department of Clinical and Experimental Sciences, University of Brescia (Italy) | D5: N = 14, mean age 73.1 ± 5.9 years, 50% female; AD diagnosis, mean duration 51.6 ± 27.6 years; CSF ≤ 600 ng/L and tau≥400 ng/L or positive PET scan; exclusion: history of TBI and medical illness other than AD | E5: Active: 12 Hz tACS,3 mA, single 60 min session; stimulation inverted after 1 week; Comparator: sham stimulation | F5: Primary: Visual search tasks Secondary: RAVL (IR + DR), TMT-A, TMT-B, MMSE pentagon test, Clockman drawing test | G5: Trial Registration: NCT05188105 | H5: ≥ 2mA | J5: ≥20 minutes
A6: Ferrazzano et al., 2025 | B6: The effects of gamma-tACS on cognitive impairment in multiple sclerosis: Arandomized, double-blind, sham-controlled,pilot study | C6: Sham-controlled, double-blind crossover study; session order was pseudo-randomized; outcome assessors and participants blinded; MS Center, Department of Human Neurosciences, Sapienza University of Rome (Italy) | D6: N = 11, 81.8% female; MS patients with deficits in verbal memory (BRB-N criteria); exclusion: clinical relapse, medical and psychiatric conditions affecting adherence to study | E6: Active: 40 Hz tACS, 1.5 mA, single 30 min session; stimulation inverted after 1 week; Comparator: sham stimulation of 7 seconds including 3-second ramp-up and ramp-down. | F6: Primary: RAVLT-IR | G6: Study grouped patients by cognitive deficits in WM, IPS and VM. Data synthesis focuses only on the VM group. | J6: ≥20 minutes
A7: Cantoni et al., | B7: Home-Based Gamma Transcranial Alternating Current Stimulation in Patients With Alzheimer Disease: A Randomized Clinical Trial | C7: Sham-controlled, double-blind cross-over study; 1:1 randomized allocation by single investigator; participants and outcome assessors blinded; Neurology Unit, Department of Clinical and Experimental Sciences, University of Brescia (Italy) | D7: N = 50 (26 active, 24 sham); mean age 66.4 ± 7.1 years; 50% female; AD diagnosis (CDI criteria); CSF ≤ 600 ng/L and tau≥400 ng/L or positive PET scan; exclusion: history of TBI, medical illness other than AD, absence of compliant caregiver | E7: Active: 40 Hz tACS, 3 mA, 60 min/session, 5 days/week for 8 weeks; Home based tACS; Comparator: sham stimulation | F7: Primary: ADAS-Cog 13-item scale, RAVLT (IR + DR), CDR-SOB, Secondary: ADCS-ADL, Semantic fluency, TMT-A, TMT-B, NPI | G7: Trial Registration: NCT05643326; study had two phases (randomized, double-blind phase and open-label phase). For meta-analysis, we are only extracting data from the blinded phase and thus the study is treated as a parallel-group study. | H7: ≥ 2mA | I7: ≥10 | J7: ≥20 minutes
A8: Zhou et al., 2022 | B8: Effects of 40 Hz transcranial alternating current stimulation (tACS) on cognitive functions of patients with Alzheimer’s disease: a randomised, doubleblind, sham-controlled clinical trial | C8: Parallel-group, double-blind RCT; 1:1 SPSS generated randomization; participants, operators and outcome assessors blinded; follow-up 12 weeks; patient center in China | D8: N = 50 (23 active, 27 sham); mean age 76.95 ± 1.28 years (active), mean age 75.78 ± 1.26 years (sham); 72% female; AD patients; no iinformation on inclusion/exclusion criteria | E8: Active: 40 Hz tACS, 2 mA, 20 min/session daily for 6 weeks; Bilateral tACS over the temporal lobes; Comparator: sham stimulation | F8: Primary: ADAS-Cog, MMSE | G8: No access to direct article or supplementary materials. | H8: ≥ 2mA | I8: ≥10 | J8: ≥20 minutes
A9: Uehara et al., 2025 | B9: Cognitive and Neuropsychiatric Effects of 40 Hz tACS Simultaneously with Cognitive Exercises for Dementia: A Randomized, Crossover, Double-Blind, Sham-Controlled Study | C9: Sham-controlled, double-blind cross-over study; 1:1 randomized allocation by PROC PLAN; follow-up 12 weeks; participants and outcome assessors blinded; Riverview Health Centre (Canada) | D9: N = 42; Participants with dementia, MoCA score between 5 and 25, stable medication; exclusion: diagnosis of neurocognitive disorder like PD and epilepsy | E9: Active: 40 Hz tACS + CT, 1.5 mA, two 30-minute sessions/day, 5 days/week for 4 weeks; stimulation inverted after 8 weeks; Comparator: sham stimulation | F9: Primary: ADAS-Cog Secondary: NPI-Q, MADRS | G9: Patient characetristics are reported by treatment sequence and not by treatment assignment. | I9: ≥10 | J9: ≥20 minutes
A10: Salgado et al., 2025 | B10: Intervention With Non-Invasive Brain Stimulation and Cognitive Training for Depressive Symptomatology Associated With Breast Cancer (ONCODEP) | C10: Parallel-group, double-blind RCT; no information on randomization allocation; participants, operators and outcome assessors blinded | D10: No information on sample size; patients with breast cancer diagnosis and who are done or nearly done with treatment; exclusion: Psychiatric illness, sensitive populations (pregnant, history of dementia, epilepsy, etc) | E10: Active: 4 Hz tACS, 2 mA, 20 min/session, 15 sessions total; Comparator: sham stimulation | F10: Primary: BDI Secondary: MoCA, PROMIS | G10: Trial Registration: NCT06053775; Study also includes tDCS and OCT (online cognitive training group) but will not be included in meta-analysis | H10: ≥ 2mA | I10: ≥10 | J10: ≥20 minutes
A11: DelFelice et al., 2019 | B11: Personalized transcranial alternating current stimulation (tACS) and physical therapy to treat motor and cognitive symptoms in Parkinson's disease: A randomized cross-over trial | C11: Sham-controlled, double-blind cross-over study; 1:1 computer-generated randomization; follow-up 4 weeks; participants and outcome assessors blinded; Riverview Health Centre (Canada) | D11: N = 15, mean age 69 ± 6.3 years, 40% female; idiopathic PD diagnosis, disease mean duration 6.3 ± 6.8 years; stable dose of antiparkinsonian therapy for at least 4 weeks; off-medication motor Hoen and Yahr 1–2; exclusion: psychiatric disorder; benzodiazepine treatment and MMSE<23 | E11: Active: 30 Hz tACS (N = 6), 4 Hz (N = 11), 2 mA, 30 min/session, 10 sessions total; stimulation inverted after 4 weeks; Comparator: sham stimulation | F11: Primary: MoCA Secondary: TIB, TMT-A, TMT-B, ROCF, Digit Symbol Task, Verbal fluency, Hopkins Verbal Learning Test-Revised | G11: Trial Registration: NCT03221413, Personalized tACS | H11: ≥ 2mA | I11: ≥10 | J11: ≥20 minutes

Sheet MoCA
A1: Disorder | B1: Study | C1: Authors | D1: Year | E1: Study ID | F1: Cognitive Outcome | G1: Cognitive Domain | H1: Outcome Measure | I1: Time Point | J1: Score_mean_int | K1: Score_sd_int | L1: Score_mean_con | M1: Score_sd_con | N1: Score_med_int | O1: Score_med_cont | P1: Notes
A2: Depression | B2: Intervention With Non-Invasive Brain Stimulation and Cognitive Training for Depressive Symptomatology Associated With Breast Cancer (ONCODEP) | C2: Salgado | D2: 2025 | E2: 44 | F2: MoCA | G2: Global Cognition | H2: Total Test Score | I2: T0 | J2: 26.083 | K2: 2.765 | L2: 25.933 | M2: 2.631
